[2024-11-27T12:15:05.245-0500] {local_task_job_runner.py:123} INFO - ::group::Pre task execution logs
[2024-11-27T12:15:05.251-0500] {taskinstance.py:2613} INFO - Dependencies all met for dep_context=non-requeueable deps ti=<TaskInstance: config_with_json.get_config manual__2024-11-27T17:15:01.008920+00:00 [queued]>
[2024-11-27T12:15:05.254-0500] {taskinstance.py:2613} INFO - Dependencies all met for dep_context=requeueable deps ti=<TaskInstance: config_with_json.get_config manual__2024-11-27T17:15:01.008920+00:00 [queued]>
[2024-11-27T12:15:05.254-0500] {taskinstance.py:2866} INFO - Starting attempt 1 of 1
[2024-11-27T12:15:05.265-0500] {taskinstance.py:2889} INFO - Executing <Task(_PythonDecoratedOperator): get_config> on 2024-11-27 17:15:01.008920+00:00
[2024-11-27T12:15:05.270-0500] {logging_mixin.py:190} WARNING - /home/vanaprastha/anaconda3/lib/python3.12/site-packages/airflow/task/task_runner/standard_task_runner.py:70 DeprecationWarning: This process (pid=32520) is multi-threaded, use of fork() may lead to deadlocks in the child.
[2024-11-27T12:15:05.270-0500] {standard_task_runner.py:104} INFO - Running: ['airflow', 'tasks', 'run', 'config_with_json', 'get_config', 'manual__2024-11-27T17:15:01.008920+00:00', '--job-id', '52', '--raw', '--subdir', 'DAGS_FOLDER/PART 3/resources/dag-config/config_with_json.py', '--cfg-path', '/tmp/tmpbhgdtm7y']
[2024-11-27T12:15:05.271-0500] {standard_task_runner.py:72} INFO - Started process 32527 to run task
[2024-11-27T12:15:05.271-0500] {standard_task_runner.py:105} INFO - Job 52: Subtask get_config
[2024-11-27T12:15:05.295-0500] {task_command.py:467} INFO - Running <TaskInstance: config_with_json.get_config manual__2024-11-27T17:15:01.008920+00:00 [running]> on host VanaPrastha
[2024-11-27T12:15:05.334-0500] {taskinstance.py:3132} INFO - Exporting env vars: AIRFLOW_CTX_DAG_OWNER='airflow' AIRFLOW_CTX_DAG_ID='config_with_json' AIRFLOW_CTX_TASK_ID='get_config' AIRFLOW_CTX_EXECUTION_DATE='2024-11-27T17:15:01.008920+00:00' AIRFLOW_CTX_TRY_NUMBER='1' AIRFLOW_CTX_DAG_RUN_ID='manual__2024-11-27T17:15:01.008920+00:00'
[2024-11-27T12:15:05.335-0500] {logging_mixin.py:190} INFO - Task instance is in running state
[2024-11-27T12:15:05.335-0500] {logging_mixin.py:190} INFO -  Previous state of the Task instance: queued
[2024-11-27T12:15:05.335-0500] {logging_mixin.py:190} INFO - Current task name:get_config state:running start_date:2024-11-27 17:15:05.251663+00:00
[2024-11-27T12:15:05.335-0500] {logging_mixin.py:190} INFO - Dag name:config_with_json and current dag run status:running
[2024-11-27T12:15:05.335-0500] {taskinstance.py:731} INFO - ::endgroup::
[2024-11-27T12:15:05.336-0500] {taskinstance.py:3311} ERROR - Task failed with exception
Traceback (most recent call last):
  File "/home/vanaprastha/anaconda3/lib/python3.12/site-packages/airflow/models/taskinstance.py", line 767, in _execute_task
    result = _execute_callable(context=context, **execute_callable_kwargs)
             ^^^^^^^^^^^^^^^^^^^^^^^^^^^^^^^^^^^^^^^^^^^^^^^^^^^^^^^^^^^^^
  File "/home/vanaprastha/anaconda3/lib/python3.12/site-packages/airflow/models/taskinstance.py", line 733, in _execute_callable
    return ExecutionCallableRunner(
           ^^^^^^^^^^^^^^^^^^^^^^^^
  File "/home/vanaprastha/anaconda3/lib/python3.12/site-packages/airflow/utils/operator_helpers.py", line 252, in run
    return self.func(*args, **kwargs)
           ^^^^^^^^^^^^^^^^^^^^^^^^^^
  File "/home/vanaprastha/anaconda3/lib/python3.12/site-packages/airflow/models/baseoperator.py", line 417, in wrapper
    return func(self, *args, **kwargs)
           ^^^^^^^^^^^^^^^^^^^^^^^^^^^
  File "/home/vanaprastha/anaconda3/lib/python3.12/site-packages/airflow/decorators/base.py", line 266, in execute
    return_value = super().execute(context)
                   ^^^^^^^^^^^^^^^^^^^^^^^^
  File "/home/vanaprastha/anaconda3/lib/python3.12/site-packages/airflow/models/baseoperator.py", line 417, in wrapper
    return func(self, *args, **kwargs)
           ^^^^^^^^^^^^^^^^^^^^^^^^^^^
  File "/home/vanaprastha/anaconda3/lib/python3.12/site-packages/airflow/operators/python.py", line 238, in execute
    return_value = self.execute_callable()
                   ^^^^^^^^^^^^^^^^^^^^^^^
  File "/home/vanaprastha/anaconda3/lib/python3.12/site-packages/airflow/operators/python.py", line 256, in execute_callable
    return runner.run(*self.op_args, **self.op_kwargs)
           ^^^^^^^^^^^^^^^^^^^^^^^^^^^^^^^^^^^^^^^^^^^
  File "/home/vanaprastha/anaconda3/lib/python3.12/site-packages/airflow/utils/operator_helpers.py", line 252, in run
    return self.func(*args, **kwargs)
           ^^^^^^^^^^^^^^^^^^^^^^^^^^
  File "/home/vanaprastha/airflow/dags/PART 3/resources/dag-config/config_with_json.py", line 12, in get_config
    with open("dags/resources/dag-config/data.json", "r") as f:
         ^^^^^^^^^^^^^^^^^^^^^^^^^^^^^^^^^^^^^^^^^^^^^^^^
FileNotFoundError: [Errno 2] No such file or directory: 'dags/resources/dag-config/data.json'
[2024-11-27T12:15:05.338-0500] {logging_mixin.py:190} INFO - Task instance in failure state
[2024-11-27T12:15:05.339-0500] {logging_mixin.py:190} INFO - Task start:2024-11-27 17:15:05.251663+00:00 end:2024-11-27 17:15:05.338764+00:00 duration:0.087101
[2024-11-27T12:15:05.339-0500] {logging_mixin.py:190} INFO - Task:<Task(_PythonDecoratedOperator): get_config> dag:<DAG: config_with_json> dagrun:<DagRun config_with_json @ 2024-11-27 17:15:01.008920+00:00: manual__2024-11-27T17:15:01.008920+00:00, state:running, queued_at: 2024-11-27 17:15:01.024986+00:00. externally triggered: True>
[2024-11-27T12:15:05.339-0500] {logging_mixin.py:190} INFO - Failure caused by [Errno 2] No such file or directory: 'dags/resources/dag-config/data.json'
[2024-11-27T12:15:05.339-0500] {taskinstance.py:1225} INFO - Marking task as FAILED. dag_id=config_with_json, task_id=get_config, run_id=manual__2024-11-27T17:15:01.008920+00:00, execution_date=20241127T171501, start_date=20241127T171505, end_date=20241127T171505
[2024-11-27T12:15:05.349-0500] {taskinstance.py:340} INFO - ::group::Post task execution logs
[2024-11-27T12:15:05.350-0500] {standard_task_runner.py:124} ERROR - Failed to execute job 52 for task get_config ([Errno 2] No such file or directory: 'dags/resources/dag-config/data.json'; 32527)
Traceback (most recent call last):
  File "/home/vanaprastha/anaconda3/lib/python3.12/site-packages/airflow/task/task_runner/standard_task_runner.py", line 117, in _start_by_fork
    ret = args.func(args, dag=self.dag)
          ^^^^^^^^^^^^^^^^^^^^^^^^^^^^^
  File "/home/vanaprastha/anaconda3/lib/python3.12/site-packages/airflow/cli/cli_config.py", line 49, in command
    return func(*args, **kwargs)
           ^^^^^^^^^^^^^^^^^^^^^
  File "/home/vanaprastha/anaconda3/lib/python3.12/site-packages/airflow/utils/cli.py", line 116, in wrapper
    return f(*args, **kwargs)
           ^^^^^^^^^^^^^^^^^^
  File "/home/vanaprastha/anaconda3/lib/python3.12/site-packages/airflow/cli/commands/task_command.py", line 483, in task_run
    task_return_code = _run_task_by_selected_method(args, _dag, ti)
                       ^^^^^^^^^^^^^^^^^^^^^^^^^^^^^^^^^^^^^^^^^^^^
  File "/home/vanaprastha/anaconda3/lib/python3.12/site-packages/airflow/cli/commands/task_command.py", line 256, in _run_task_by_selected_method
    return _run_raw_task(args, ti)
           ^^^^^^^^^^^^^^^^^^^^^^^
  File "/home/vanaprastha/anaconda3/lib/python3.12/site-packages/airflow/cli/commands/task_command.py", line 341, in _run_raw_task
    return ti._run_raw_task(
           ^^^^^^^^^^^^^^^^^
  File "/home/vanaprastha/anaconda3/lib/python3.12/site-packages/airflow/utils/session.py", line 97, in wrapper
    return func(*args, session=session, **kwargs)
           ^^^^^^^^^^^^^^^^^^^^^^^^^^^^^^^^^^^^^^
  File "/home/vanaprastha/anaconda3/lib/python3.12/site-packages/airflow/models/taskinstance.py", line 3005, in _run_raw_task
    return _run_raw_task(
           ^^^^^^^^^^^^^^
  File "/home/vanaprastha/anaconda3/lib/python3.12/site-packages/airflow/models/taskinstance.py", line 273, in _run_raw_task
    TaskInstance._execute_task_with_callbacks(
  File "/home/vanaprastha/anaconda3/lib/python3.12/site-packages/airflow/models/taskinstance.py", line 3159, in _execute_task_with_callbacks
    result = self._execute_task(context, task_orig)
             ^^^^^^^^^^^^^^^^^^^^^^^^^^^^^^^^^^^^^^
  File "/home/vanaprastha/anaconda3/lib/python3.12/site-packages/airflow/models/taskinstance.py", line 3183, in _execute_task
    return _execute_task(self, context, task_orig)
           ^^^^^^^^^^^^^^^^^^^^^^^^^^^^^^^^^^^^^^^
  File "/home/vanaprastha/anaconda3/lib/python3.12/site-packages/airflow/models/taskinstance.py", line 767, in _execute_task
    result = _execute_callable(context=context, **execute_callable_kwargs)
             ^^^^^^^^^^^^^^^^^^^^^^^^^^^^^^^^^^^^^^^^^^^^^^^^^^^^^^^^^^^^^
  File "/home/vanaprastha/anaconda3/lib/python3.12/site-packages/airflow/models/taskinstance.py", line 733, in _execute_callable
    return ExecutionCallableRunner(
           ^^^^^^^^^^^^^^^^^^^^^^^^
  File "/home/vanaprastha/anaconda3/lib/python3.12/site-packages/airflow/utils/operator_helpers.py", line 252, in run
    return self.func(*args, **kwargs)
           ^^^^^^^^^^^^^^^^^^^^^^^^^^
  File "/home/vanaprastha/anaconda3/lib/python3.12/site-packages/airflow/models/baseoperator.py", line 417, in wrapper
    return func(self, *args, **kwargs)
           ^^^^^^^^^^^^^^^^^^^^^^^^^^^
  File "/home/vanaprastha/anaconda3/lib/python3.12/site-packages/airflow/decorators/base.py", line 266, in execute
    return_value = super().execute(context)
                   ^^^^^^^^^^^^^^^^^^^^^^^^
  File "/home/vanaprastha/anaconda3/lib/python3.12/site-packages/airflow/models/baseoperator.py", line 417, in wrapper
    return func(self, *args, **kwargs)
           ^^^^^^^^^^^^^^^^^^^^^^^^^^^
  File "/home/vanaprastha/anaconda3/lib/python3.12/site-packages/airflow/operators/python.py", line 238, in execute
    return_value = self.execute_callable()
                   ^^^^^^^^^^^^^^^^^^^^^^^
  File "/home/vanaprastha/anaconda3/lib/python3.12/site-packages/airflow/operators/python.py", line 256, in execute_callable
    return runner.run(*self.op_args, **self.op_kwargs)
           ^^^^^^^^^^^^^^^^^^^^^^^^^^^^^^^^^^^^^^^^^^^
  File "/home/vanaprastha/anaconda3/lib/python3.12/site-packages/airflow/utils/operator_helpers.py", line 252, in run
    return self.func(*args, **kwargs)
           ^^^^^^^^^^^^^^^^^^^^^^^^^^
  File "/home/vanaprastha/airflow/dags/PART 3/resources/dag-config/config_with_json.py", line 12, in get_config
    with open("dags/resources/dag-config/data.json", "r") as f:
         ^^^^^^^^^^^^^^^^^^^^^^^^^^^^^^^^^^^^^^^^^^^^^^^^
FileNotFoundError: [Errno 2] No such file or directory: 'dags/resources/dag-config/data.json'
[2024-11-27T12:15:05.364-0500] {local_task_job_runner.py:266} INFO - Task exited with return code 1
[2024-11-27T12:15:05.375-0500] {taskinstance.py:3895} INFO - 0 downstream tasks scheduled from follow-on schedule check
[2024-11-27T12:15:05.384-0500] {local_task_job_runner.py:245} INFO - ::endgroup::
