Traceback (most recent call last):
  File "/home/vanaprastha/anaconda3/lib/python3.12/site-packages/psutil/_common.py", line 441, in wrapper
    ret = self._cache[fun]
          ^^^^^^^^^^^
AttributeError: 'Process' object has no attribute '_cache'

During handling of the above exception, another exception occurred:

Traceback (most recent call last):
  File "/home/vanaprastha/anaconda3/lib/python3.12/site-packages/psutil/_pslinux.py", line 1661, in wrapper
    return fun(self, *args, **kwargs)
           ^^^^^^^^^^^^^^^^^^^^^^^^^^
  File "/home/vanaprastha/anaconda3/lib/python3.12/site-packages/psutil/_common.py", line 444, in wrapper
    return fun(self)
           ^^^^^^^^^
  File "/home/vanaprastha/anaconda3/lib/python3.12/site-packages/psutil/_pslinux.py", line 1703, in _parse_stat_file
    with open_binary("%s/%s/stat" % (self._procfs_path, self.pid)) as f:
         ^^^^^^^^^^^^^^^^^^^^^^^^^^^^^^^^^^^^^^^^^^^^^^^^^^^^^^^^^
  File "/home/vanaprastha/anaconda3/lib/python3.12/site-packages/psutil/_common.py", line 711, in open_binary
    return open(fname, "rb", **kwargs)
           ^^^^^^^^^^^^^^^^^^^^^^^^^^^
FileNotFoundError: [Errno 2] No such file or directory: '/proc/33543/stat'

During handling of the above exception, another exception occurred:

Traceback (most recent call last):
  File "/home/vanaprastha/anaconda3/lib/python3.12/site-packages/psutil/__init__.py", line 361, in _init
    self.create_time()
  File "/home/vanaprastha/anaconda3/lib/python3.12/site-packages/psutil/__init__.py", line 717, in create_time
    self._create_time = self._proc.create_time()
                        ^^^^^^^^^^^^^^^^^^^^^^^^
  File "/home/vanaprastha/anaconda3/lib/python3.12/site-packages/psutil/_pslinux.py", line 1661, in wrapper
    return fun(self, *args, **kwargs)
           ^^^^^^^^^^^^^^^^^^^^^^^^^^
  File "/home/vanaprastha/anaconda3/lib/python3.12/site-packages/psutil/_pslinux.py", line 1873, in create_time
    ctime = float(self._parse_stat_file()['create_time'])
                  ^^^^^^^^^^^^^^^^^^^^^^^
  File "/home/vanaprastha/anaconda3/lib/python3.12/site-packages/psutil/_pslinux.py", line 1668, in wrapper
    raise NoSuchProcess(self.pid, self._name)
psutil.NoSuchProcess: process no longer exists (pid=33543)

During handling of the above exception, another exception occurred:

Traceback (most recent call last):
  File "/home/vanaprastha/anaconda3/bin/airflow", line 8, in <module>
    sys.exit(main())
             ^^^^^^
  File "/home/vanaprastha/anaconda3/lib/python3.12/site-packages/airflow/__main__.py", line 62, in main
    args.func(args)
  File "/home/vanaprastha/anaconda3/lib/python3.12/site-packages/airflow/cli/cli_config.py", line 49, in command
    return func(*args, **kwargs)
           ^^^^^^^^^^^^^^^^^^^^^
  File "/home/vanaprastha/anaconda3/lib/python3.12/site-packages/airflow/utils/cli.py", line 116, in wrapper
    return f(*args, **kwargs)
           ^^^^^^^^^^^^^^^^^^
  File "/home/vanaprastha/anaconda3/lib/python3.12/site-packages/airflow/utils/providers_configuration_loader.py", line 55, in wrapped_function
    return func(*args, **kwargs)
           ^^^^^^^^^^^^^^^^^^^^^
  File "/home/vanaprastha/anaconda3/lib/python3.12/site-packages/airflow/cli/commands/webserver_command.py", line 485, in webserver
    run_command_with_daemon_option(
  File "/home/vanaprastha/anaconda3/lib/python3.12/site-packages/airflow/cli/commands/daemon_utils.py", line 81, in run_command_with_daemon_option
    callback()
  File "/home/vanaprastha/anaconda3/lib/python3.12/site-packages/airflow/cli/commands/webserver_command.py", line 488, in <lambda>
    callback=lambda: start_and_monitor_gunicorn(args),
                     ^^^^^^^^^^^^^^^^^^^^^^^^^^^^^^^^
  File "/home/vanaprastha/anaconda3/lib/python3.12/site-packages/airflow/cli/commands/webserver_command.py", line 471, in start_and_monitor_gunicorn
    gunicorn_master_proc = psutil.Process(gunicorn_master_proc_pid)
                           ^^^^^^^^^^^^^^^^^^^^^^^^^^^^^^^^^^^^^^^^
  File "/home/vanaprastha/anaconda3/lib/python3.12/site-packages/psutil/__init__.py", line 332, in __init__
    self._init(pid)
  File "/home/vanaprastha/anaconda3/lib/python3.12/site-packages/psutil/__init__.py", line 373, in _init
    raise NoSuchProcess(pid, msg='process PID not found')
psutil.NoSuchProcess: process PID not found (pid=33543)
/home/vanaprastha/anaconda3/lib/python3.12/site-packages/airflow/configuration.py:859 FutureWarning: section/key [core/sql_alchemy_conn] has been deprecated, you should use[database/sql_alchemy_conn] instead. Please update your `conf.get*` call to use the new name
