[2024-11-27T05:18:19.075-0500] {local_task_job_runner.py:123} INFO - ::group::Pre task execution logs
[2024-11-27T05:18:19.081-0500] {taskinstance.py:2613} INFO - Dependencies all met for dep_context=non-requeueable deps ti=<TaskInstance: rocket_launch_pipeline.fetch_rocket_data scheduled__2024-01-07T06:00:00+00:00 [queued]>
[2024-11-27T05:18:19.084-0500] {taskinstance.py:2613} INFO - Dependencies all met for dep_context=requeueable deps ti=<TaskInstance: rocket_launch_pipeline.fetch_rocket_data scheduled__2024-01-07T06:00:00+00:00 [queued]>
[2024-11-27T05:18:19.084-0500] {taskinstance.py:2866} INFO - Starting attempt 1 of 4
[2024-11-27T05:18:19.096-0500] {taskinstance.py:2889} INFO - Executing <Task(BashOperator): fetch_rocket_data> on 2024-01-07 06:00:00+00:00
[2024-11-27T05:18:19.102-0500] {logging_mixin.py:190} WARNING - /home/vanaprastha/anaconda3/lib/python3.12/site-packages/airflow/task/task_runner/standard_task_runner.py:70 DeprecationWarning: This process (pid=12689) is multi-threaded, use of fork() may lead to deadlocks in the child.
[2024-11-27T05:18:19.103-0500] {standard_task_runner.py:72} INFO - Started process 12696 to run task
[2024-11-27T05:18:19.102-0500] {standard_task_runner.py:104} INFO - Running: ['airflow', 'tasks', 'run', 'rocket_launch_pipeline', 'fetch_rocket_data', 'scheduled__2024-01-07T06:00:00+00:00', '--job-id', '15', '--raw', '--subdir', 'DAGS_FOLDER/rocket_launch.py', '--cfg-path', '/tmp/tmpwx690rf2']
[2024-11-27T05:18:19.103-0500] {standard_task_runner.py:105} INFO - Job 15: Subtask fetch_rocket_data
[2024-11-27T05:18:19.131-0500] {task_command.py:467} INFO - Running <TaskInstance: rocket_launch_pipeline.fetch_rocket_data scheduled__2024-01-07T06:00:00+00:00 [running]> on host VanaPrastha
[2024-11-27T05:18:19.173-0500] {taskinstance.py:3132} INFO - Exporting env vars: AIRFLOW_CTX_DAG_OWNER='airflow' AIRFLOW_CTX_DAG_ID='rocket_launch_pipeline' AIRFLOW_CTX_TASK_ID='fetch_rocket_data' AIRFLOW_CTX_EXECUTION_DATE='2024-01-07T06:00:00+00:00' AIRFLOW_CTX_TRY_NUMBER='1' AIRFLOW_CTX_DAG_RUN_ID='scheduled__2024-01-07T06:00:00+00:00'
[2024-11-27T05:18:19.173-0500] {logging_mixin.py:190} INFO - Task instance is in running state
[2024-11-27T05:18:19.173-0500] {logging_mixin.py:190} INFO -  Previous state of the Task instance: queued
[2024-11-27T05:18:19.173-0500] {logging_mixin.py:190} INFO - Current task name:fetch_rocket_data state:running start_date:2024-11-27 10:18:19.081985+00:00
[2024-11-27T05:18:19.174-0500] {logging_mixin.py:190} INFO - Dag name:rocket_launch_pipeline and current dag run status:running
[2024-11-27T05:18:19.174-0500] {taskinstance.py:731} INFO - ::endgroup::
[2024-11-27T05:18:19.174-0500] {subprocess.py:78} INFO - Tmp dir root location: /tmp
[2024-11-27T05:18:19.174-0500] {subprocess.py:88} INFO - Running command: ['/usr/bin/bash', '-c', 'curl -L -o /tmp/launches.json https://llapi.thespacedevs.com/2.2.0/launch/upcoming']
[2024-11-27T05:18:19.183-0500] {subprocess.py:99} INFO - Output:
[2024-11-27T05:18:19.187-0500] {subprocess.py:106} INFO -   % Total    % Received % Xferd  Average Speed   Time    Time     Time  Current
[2024-11-27T05:18:19.187-0500] {subprocess.py:106} INFO -                                  Dload  Upload   Total   Spent    Left  Speed
[2024-11-27T05:18:19.823-0500] {subprocess.py:106} INFO -   0     0    0     0    0     0      0      0 --:--:-- --:--:-- --:--:--     0  0     0    0     0    0     0      0      0 --:--:-- --:--:-- --:--:--     0
[2024-11-27T05:18:19.824-0500] {subprocess.py:106} INFO - curl: (60) SSL certificate problem: self-signed certificate
[2024-11-27T05:18:19.824-0500] {subprocess.py:106} INFO - More details here: https://curl.se/docs/sslcerts.html
[2024-11-27T05:18:19.824-0500] {subprocess.py:106} INFO - 
[2024-11-27T05:18:19.824-0500] {subprocess.py:106} INFO - curl failed to verify the legitimacy of the server and therefore could not
[2024-11-27T05:18:19.824-0500] {subprocess.py:106} INFO - establish a secure connection to it. To learn more about this situation and
[2024-11-27T05:18:19.824-0500] {subprocess.py:106} INFO - how to fix it, please visit the webpage mentioned above.
[2024-11-27T05:18:19.825-0500] {subprocess.py:110} INFO - Command exited with return code 60
[2024-11-27T05:18:19.835-0500] {taskinstance.py:3311} ERROR - Task failed with exception
Traceback (most recent call last):
  File "/home/vanaprastha/anaconda3/lib/python3.12/site-packages/airflow/models/taskinstance.py", line 767, in _execute_task
    result = _execute_callable(context=context, **execute_callable_kwargs)
             ^^^^^^^^^^^^^^^^^^^^^^^^^^^^^^^^^^^^^^^^^^^^^^^^^^^^^^^^^^^^^
  File "/home/vanaprastha/anaconda3/lib/python3.12/site-packages/airflow/models/taskinstance.py", line 733, in _execute_callable
    return ExecutionCallableRunner(
           ^^^^^^^^^^^^^^^^^^^^^^^^
  File "/home/vanaprastha/anaconda3/lib/python3.12/site-packages/airflow/utils/operator_helpers.py", line 252, in run
    return self.func(*args, **kwargs)
           ^^^^^^^^^^^^^^^^^^^^^^^^^^
  File "/home/vanaprastha/anaconda3/lib/python3.12/site-packages/airflow/models/baseoperator.py", line 417, in wrapper
    return func(self, *args, **kwargs)
           ^^^^^^^^^^^^^^^^^^^^^^^^^^^
  File "/home/vanaprastha/anaconda3/lib/python3.12/site-packages/airflow/operators/bash.py", line 276, in execute
    raise AirflowException(
airflow.exceptions.AirflowException: Bash command failed. The command returned a non-zero exit code 60.
[2024-11-27T05:18:19.872-0500] {logging_mixin.py:190} INFO - Task instance in failure state
[2024-11-27T05:18:19.872-0500] {logging_mixin.py:190} INFO - Task start:2024-11-27 10:18:19.081985+00:00 end:2024-11-27 10:18:19.872113+00:00 duration:0.790128
[2024-11-27T05:18:19.872-0500] {logging_mixin.py:190} INFO - Task:<Task(BashOperator): fetch_rocket_data> dag:<DAG: rocket_launch_pipeline> dagrun:<DagRun rocket_launch_pipeline @ 2024-01-07 06:00:00+00:00: scheduled__2024-01-07T06:00:00+00:00, state:running, queued_at: 2024-11-27 10:18:17.113152+00:00. externally triggered: False>
[2024-11-27T05:18:19.872-0500] {logging_mixin.py:190} INFO - Failure caused by Bash command failed. The command returned a non-zero exit code 60.
[2024-11-27T05:18:19.873-0500] {taskinstance.py:1225} INFO - Marking task as UP_FOR_RETRY. dag_id=rocket_launch_pipeline, task_id=fetch_rocket_data, run_id=scheduled__2024-01-07T06:00:00+00:00, execution_date=20240107T060000, start_date=20241127T101819, end_date=20241127T101819
[2024-11-27T05:18:19.890-0500] {taskinstance.py:340} INFO - ::group::Post task execution logs
[2024-11-27T05:18:19.891-0500] {standard_task_runner.py:124} ERROR - Failed to execute job 15 for task fetch_rocket_data (Bash command failed. The command returned a non-zero exit code 60.; 12696)
Traceback (most recent call last):
  File "/home/vanaprastha/anaconda3/lib/python3.12/site-packages/airflow/task/task_runner/standard_task_runner.py", line 117, in _start_by_fork
    ret = args.func(args, dag=self.dag)
          ^^^^^^^^^^^^^^^^^^^^^^^^^^^^^
  File "/home/vanaprastha/anaconda3/lib/python3.12/site-packages/airflow/cli/cli_config.py", line 49, in command
    return func(*args, **kwargs)
           ^^^^^^^^^^^^^^^^^^^^^
  File "/home/vanaprastha/anaconda3/lib/python3.12/site-packages/airflow/utils/cli.py", line 116, in wrapper
    return f(*args, **kwargs)
           ^^^^^^^^^^^^^^^^^^
  File "/home/vanaprastha/anaconda3/lib/python3.12/site-packages/airflow/cli/commands/task_command.py", line 483, in task_run
    task_return_code = _run_task_by_selected_method(args, _dag, ti)
                       ^^^^^^^^^^^^^^^^^^^^^^^^^^^^^^^^^^^^^^^^^^^^
  File "/home/vanaprastha/anaconda3/lib/python3.12/site-packages/airflow/cli/commands/task_command.py", line 256, in _run_task_by_selected_method
    return _run_raw_task(args, ti)
           ^^^^^^^^^^^^^^^^^^^^^^^
  File "/home/vanaprastha/anaconda3/lib/python3.12/site-packages/airflow/cli/commands/task_command.py", line 341, in _run_raw_task
    return ti._run_raw_task(
           ^^^^^^^^^^^^^^^^^
  File "/home/vanaprastha/anaconda3/lib/python3.12/site-packages/airflow/utils/session.py", line 97, in wrapper
    return func(*args, session=session, **kwargs)
           ^^^^^^^^^^^^^^^^^^^^^^^^^^^^^^^^^^^^^^
  File "/home/vanaprastha/anaconda3/lib/python3.12/site-packages/airflow/models/taskinstance.py", line 3005, in _run_raw_task
    return _run_raw_task(
           ^^^^^^^^^^^^^^
  File "/home/vanaprastha/anaconda3/lib/python3.12/site-packages/airflow/models/taskinstance.py", line 273, in _run_raw_task
    TaskInstance._execute_task_with_callbacks(
  File "/home/vanaprastha/anaconda3/lib/python3.12/site-packages/airflow/models/taskinstance.py", line 3159, in _execute_task_with_callbacks
    result = self._execute_task(context, task_orig)
             ^^^^^^^^^^^^^^^^^^^^^^^^^^^^^^^^^^^^^^
  File "/home/vanaprastha/anaconda3/lib/python3.12/site-packages/airflow/models/taskinstance.py", line 3183, in _execute_task
    return _execute_task(self, context, task_orig)
           ^^^^^^^^^^^^^^^^^^^^^^^^^^^^^^^^^^^^^^^
  File "/home/vanaprastha/anaconda3/lib/python3.12/site-packages/airflow/models/taskinstance.py", line 767, in _execute_task
    result = _execute_callable(context=context, **execute_callable_kwargs)
             ^^^^^^^^^^^^^^^^^^^^^^^^^^^^^^^^^^^^^^^^^^^^^^^^^^^^^^^^^^^^^
  File "/home/vanaprastha/anaconda3/lib/python3.12/site-packages/airflow/models/taskinstance.py", line 733, in _execute_callable
    return ExecutionCallableRunner(
           ^^^^^^^^^^^^^^^^^^^^^^^^
  File "/home/vanaprastha/anaconda3/lib/python3.12/site-packages/airflow/utils/operator_helpers.py", line 252, in run
    return self.func(*args, **kwargs)
           ^^^^^^^^^^^^^^^^^^^^^^^^^^
  File "/home/vanaprastha/anaconda3/lib/python3.12/site-packages/airflow/models/baseoperator.py", line 417, in wrapper
    return func(self, *args, **kwargs)
           ^^^^^^^^^^^^^^^^^^^^^^^^^^^
  File "/home/vanaprastha/anaconda3/lib/python3.12/site-packages/airflow/operators/bash.py", line 276, in execute
    raise AirflowException(
airflow.exceptions.AirflowException: Bash command failed. The command returned a non-zero exit code 60.
[2024-11-27T05:18:19.918-0500] {local_task_job_runner.py:266} INFO - Task exited with return code 1
[2024-11-27T05:18:19.927-0500] {taskinstance.py:3895} INFO - 0 downstream tasks scheduled from follow-on schedule check
[2024-11-27T05:18:19.927-0500] {local_task_job_runner.py:245} INFO - ::endgroup::
