[2024-11-27T12:33:53.568-0500] {local_task_job_runner.py:123} INFO - ::group::Pre task execution logs
[2024-11-27T12:33:53.574-0500] {taskinstance.py:2613} INFO - Dependencies all met for dep_context=non-requeueable deps ti=<TaskInstance: sensor_file.wait_file scheduled__2024-11-27T17:20:00+00:00 [queued]>
[2024-11-27T12:33:53.578-0500] {taskinstance.py:2613} INFO - Dependencies all met for dep_context=requeueable deps ti=<TaskInstance: sensor_file.wait_file scheduled__2024-11-27T17:20:00+00:00 [queued]>
[2024-11-27T12:33:53.578-0500] {taskinstance.py:2866} INFO - Starting attempt 3 of 1
[2024-11-27T12:33:53.589-0500] {taskinstance.py:2889} INFO - Executing <Task(FileSensor): wait_file> on 2024-11-27 17:20:00+00:00
[2024-11-27T12:33:53.597-0500] {logging_mixin.py:190} WARNING - /home/vanaprastha/anaconda3/lib/python3.12/site-packages/airflow/task/task_runner/standard_task_runner.py:70 DeprecationWarning: This process (pid=34026) is multi-threaded, use of fork() may lead to deadlocks in the child.
[2024-11-27T12:33:53.597-0500] {standard_task_runner.py:104} INFO - Running: ['airflow', 'tasks', 'run', 'sensor_file', 'wait_file', 'scheduled__2024-11-27T17:20:00+00:00', '--job-id', '78', '--raw', '--subdir', 'DAGS_FOLDER/PART 3/Sensor/sensor_file.py', '--cfg-path', '/tmp/tmpautx98ag']
[2024-11-27T12:33:53.598-0500] {standard_task_runner.py:72} INFO - Started process 34034 to run task
[2024-11-27T12:33:53.598-0500] {standard_task_runner.py:105} INFO - Job 78: Subtask wait_file
[2024-11-27T12:33:53.623-0500] {task_command.py:467} INFO - Running <TaskInstance: sensor_file.wait_file scheduled__2024-11-27T17:20:00+00:00 [running]> on host VanaPrastha
[2024-11-27T12:33:53.664-0500] {taskinstance.py:3132} INFO - Exporting env vars: AIRFLOW_CTX_DAG_OWNER='airflow' AIRFLOW_CTX_DAG_ID='sensor_file' AIRFLOW_CTX_TASK_ID='wait_file' AIRFLOW_CTX_EXECUTION_DATE='2024-11-27T17:20:00+00:00' AIRFLOW_CTX_TRY_NUMBER='3' AIRFLOW_CTX_DAG_RUN_ID='scheduled__2024-11-27T17:20:00+00:00'
[2024-11-27T12:33:53.665-0500] {logging_mixin.py:190} INFO - Task instance is in running state
[2024-11-27T12:33:53.666-0500] {logging_mixin.py:190} INFO -  Previous state of the Task instance: queued
[2024-11-27T12:33:53.666-0500] {logging_mixin.py:190} INFO - Current task name:wait_file state:running start_date:2024-11-27 17:33:53.575032+00:00
[2024-11-27T12:33:53.666-0500] {logging_mixin.py:190} INFO - Dag name:sensor_file and current dag run status:running
[2024-11-27T12:33:53.666-0500] {taskinstance.py:731} INFO - ::endgroup::
[2024-11-27T12:33:53.666-0500] {baseoperator.py:416} WARNING - FileSensor.execute cannot be called outside TaskInstance!
[2024-11-27T12:33:53.672-0500] {base.py:84} INFO - Retrieving connection 'fs_default'
[2024-11-27T12:33:53.672-0500] {filesystem.py:109} INFO - Poking for file /watch/text.txt
[2024-11-27T12:33:58.672-0500] {filesystem.py:109} INFO - Poking for file /watch/text.txt
[2024-11-27T12:34:03.673-0500] {filesystem.py:109} INFO - Poking for file /watch/text.txt
[2024-11-27T12:34:08.673-0500] {filesystem.py:109} INFO - Poking for file /watch/text.txt
[2024-11-27T12:34:08.799-0500] {local_task_job_runner.py:346} WARNING - State of this instance has been externally set to queued. Terminating instance.
[2024-11-27T12:34:08.799-0500] {local_task_job_runner.py:245} INFO - ::endgroup::
[2024-11-27T12:34:08.808-0500] {process_utils.py:132} INFO - Sending 15 to group 34034. PIDs of all processes in the group: [34034]
[2024-11-27T12:34:08.809-0500] {process_utils.py:87} INFO - Sending the signal 15 to group 34034
[2024-11-27T12:34:08.809-0500] {taskinstance.py:3093} ERROR - Received SIGTERM. Terminating subprocesses.
[2024-11-27T12:34:08.813-0500] {taskinstance.py:3311} ERROR - Task failed with exception
Traceback (most recent call last):
  File "/home/vanaprastha/anaconda3/lib/python3.12/site-packages/airflow/models/taskinstance.py", line 767, in _execute_task
    result = _execute_callable(context=context, **execute_callable_kwargs)
             ^^^^^^^^^^^^^^^^^^^^^^^^^^^^^^^^^^^^^^^^^^^^^^^^^^^^^^^^^^^^^
  File "/home/vanaprastha/anaconda3/lib/python3.12/site-packages/airflow/models/taskinstance.py", line 733, in _execute_callable
    return ExecutionCallableRunner(
           ^^^^^^^^^^^^^^^^^^^^^^^^
  File "/home/vanaprastha/anaconda3/lib/python3.12/site-packages/airflow/utils/operator_helpers.py", line 252, in run
    return self.func(*args, **kwargs)
           ^^^^^^^^^^^^^^^^^^^^^^^^^^
  File "/home/vanaprastha/anaconda3/lib/python3.12/site-packages/airflow/models/baseoperator.py", line 417, in wrapper
    return func(self, *args, **kwargs)
           ^^^^^^^^^^^^^^^^^^^^^^^^^^^
  File "/home/vanaprastha/anaconda3/lib/python3.12/site-packages/airflow/sensors/filesystem.py", line 123, in execute
    super().execute(context=context)
  File "/home/vanaprastha/anaconda3/lib/python3.12/site-packages/airflow/models/baseoperator.py", line 417, in wrapper
    return func(self, *args, **kwargs)
           ^^^^^^^^^^^^^^^^^^^^^^^^^^^
  File "/home/vanaprastha/anaconda3/lib/python3.12/site-packages/airflow/sensors/base.py", line 334, in execute
    time.sleep(self._get_next_poke_interval(started_at, run_duration, poke_count))
  File "/home/vanaprastha/anaconda3/lib/python3.12/site-packages/airflow/models/taskinstance.py", line 3095, in signal_handler
    raise AirflowTaskTerminated("Task received SIGTERM signal")
airflow.exceptions.AirflowTaskTerminated: Task received SIGTERM signal
[2024-11-27T12:34:08.818-0500] {logging_mixin.py:190} INFO - Task instance in failure state
[2024-11-27T12:34:08.818-0500] {logging_mixin.py:190} INFO - Task start:2024-11-27 17:33:53.575032+00:00 end:2024-11-27 17:34:08.817820+00:00 duration:15.242788
[2024-11-27T12:34:08.818-0500] {logging_mixin.py:190} INFO - Task:<Task(FileSensor): wait_file> dag:<DAG: sensor_file> dagrun:<DagRun sensor_file @ 2024-11-27 17:20:00+00:00: scheduled__2024-11-27T17:20:00+00:00, state:running, queued_at: 2024-11-27 17:21:30.272649+00:00. externally triggered: False>
[2024-11-27T12:34:08.819-0500] {logging_mixin.py:190} INFO - Failure caused by Task received SIGTERM signal
[2024-11-27T12:34:08.819-0500] {taskinstance.py:1225} INFO - Marking task as FAILED. dag_id=sensor_file, task_id=wait_file, run_id=scheduled__2024-11-27T17:20:00+00:00, execution_date=20241127T172000, start_date=20241127T173353, end_date=20241127T173408
[2024-11-27T12:34:08.830-0500] {taskinstance.py:340} INFO - ::group::Post task execution logs
[2024-11-27T12:34:08.861-0500] {process_utils.py:80} INFO - Process psutil.Process(pid=34034, status='terminated', exitcode=2, started='12:33:53') (34034) terminated with exit code 2
